Workbook

Sheet Ghid
A1: Strategia de prețuri – Travel Concept - Silver Mountain (A13)
A2: Un singur loc de modificare: foaia „Sezoane” (+ setările din „Platforme”). Restul se calculează automat.
A4: PRINCIPIUL
A5: 1. Pe site câștigi cu 5% mai mult decât pe platforme (reglabil în „Platforme” B31). | B5: Prețul de pe fiecare platformă se calculează din tariful site-ului: câștigul net de pe site ÷ 1,05, apoi „umflat” cu comisionul și reducerile automate ale platformei.
A6: 2. Pe site, oaspetele plătește cel mai puțin. | B6: Diferența față de platforme e egală cu comisionul economisit (12–16%). E un motiv clar să rezerve direct. Din dec. 2024 Booking nu mai poate impune paritatea de preț în UE (DMA).
A7: 3. Aceleași sezoane, aceleași nopți minime, aceleași reduceri pe durată – peste tot. | B7: Sezoanele și regulile se definesc o singură dată și se copiază pe platforme după lista din „Checklist”.
A9: CUM SE FOLOSEȘTE
A10: Pas 1 – Sezoane | B10: Modifici doar celulele galbene cu text albastru: perioade, tarif site, nopți minime, reduceri pe durată.
A11: Pas 2 – Platforme | B11: Verifici comisioanele și reducerile automate (ex. mobil Booking 10%). Se schimbă rar. Tot aici alegi cât ții cont de sugestiile de preț Airbnb.
A12: Pas 3 – Prețuri de setat | B12: Citești prețul calculat pentru fiecare platformă și sezon. Coloanele „Acum” arată ce e setat azi; roșu = diferă.
A13: Pas 4 – Checklist | B13: Setezi prețurile pe Booking, Airbnb, Travelminit și bifezi.
A14: Pas 5 – Site | B14: Salvezi fișierul ca pricing/tarife.xlsx în repo și faci push: site-ul se actualizează singur (foaia „Export site”).
A15: Verificare | B15: Foaia „Verificare” semnalează suprapuneri, goluri între sezoane și sezoane neordonate.
A16: Simulator | B16: Alegi data, nopțile și adulții: vezi cât plătește oaspetele și cât câștigi pe fiecare canal.
A17: Calendar | B17: Prețul zi cu zi pentru 12 luni, pe fiecare canal – util când introduci prețuri pe intervale în extranet.
A19: LEGENDĂ
A20: Celulă galbenă, text albastru | B20: Date de intrare – le poți modifica.
A21: Celulă albastru-deschis | B21: Calculat automat – nu modifica.
A22: Text verde | B22: Preluat din altă foaie.
A24: IMPORTANT
A25: Foaia „Export site” | B25: O citește automat site-ul (scriptul update-pricing.cjs). Nu o redenumi, nu o șterge, nu scrie în ea.
A26: Ordinea sezoanelor | B26: Sezoanele trebuie scrise în ordine cronologică, fără suprapuneri.
A27: Platformele nu se actualizează singure | B27: Booking, Airbnb și Travelminit se setează manual (sau printr-un channel manager). Excelul îți spune exact ce valori să pui.
A28: Date colectate | B28: Comisioanele și prețurile actuale au fost citite din conturi pe 21.10.2026 – vezi foaia „Date actuale”.

Sheet Sezoane
A1: Sezoane – singurul loc unde modifici prețurile
A2: Tarif site = prețul pe noapte plătit de oaspete la rezervare directă, cu taxele locale incluse, înainte de reducerile pe durată. Reducere goală = fără reducere pentru acea durată.
A3: Scrie sezoanele în ordine cronologică. Rânduri libere: până la rândul 40.
A5: ID sezon | B5: Denumire | C5: Data început | D5: Data sfârșit | E5: Tarif site / noapte | F5: Nopți minime | G5: Reducere 2 nopți | H5: Reducere 3 nopți | I5: Reducere 4 nopți | J5: Reducere 5 nopți | K5: Reducere 6 nopți | L5: Reducere 7+ nopți | M5: Politică anulare (platforme) | N5: Observații | O5: Sugestie Airbnb / noapte (opțional)
A6: vara-toamna-2026 | B6: Sezon vară | C6: 46204 | D6: 46356 | E6: 900 | F6: 2 | G6: 0.1 | H6: 0.15 | I6: 0.2 | J6: 0.25 | K6: 0.3 | L6: 0.33 | M6: Flexibil 14 zile | O6: 474
A7: iarna-2026 | B7: Sezon iarnă | C7: 46357 | D7: 46376 | E7: 1250 | F7: 2 | G7: 0.1 | H7: 0.15 | I7: 0.2 | J7: 0.25 | K7: 0.3 | L7: 0.33 | M7: Flexibil 14 zile
A8: Craciun-2026 | B8: Sezon iarnă | C8: 46377 | D8: 46383 | E8: 1500 | F8: 3 | H8: 0 | M8: Nerambursabil | N8: Sărbători: fără reduceri pe durată
A9: Revelion-2026-2027 | B9: Sezon iarnă | C9: 46384 | D9: 46391 | E9: 1800 | F9: 4 | I9: 0 | M9: Nerambursabil | N9: Sărbători: fără reduceri pe durată
A10: iarna-2027 | B10: Sezon iarnă | C10: 46392 | D10: 46432 | E10: 1350 | F10: 2 | G10: 0.1 | H10: 0.15 | I10: 0.2 | J10: 0.25 | K10: 0.3 | L10: 0.33 | M10: Flexibil 14 zile
A11: Vacanta-schi-2027 | B11: Sezon iarnă | C11: 46433 | D11: 46453 | E11: 1450 | F11: 2 | G11: 0.1 | H11: 0.15 | I11: 0.2 | J11: 0.25 | K11: 0.3 | L11: 0.33 | M11: Flexibil 14 zile | N11: După 07.03.2027 nu există sezon pe site → rezervări directe blocate

Sheet Platforme
A1: Platforme – comisioane, reduceri automate, taxe
A2: Se modifică rar. Valorile au fost verificate în conturi pe 21.10.2026 (vezi „Date actuale”).
A4: Taxe locale incluse în preț (pe noapte)
A5: Taxă turistică / adult / noapte | B5: 7
A6: Taxă Salvamont / adult / noapte | B6: 5
A7: Adulți luați în calcul (ocupare tipică) | B7: 4
A8: Taxe locale / noapte (calculat) | B8: =(B5+B6)*B7 -> 48
A10: Setare | B10: Site direct | C10: Booking.com | D10: Airbnb | E10: Travelminit | F10: Sursă / explicație
A11: Comision platformă | B11: 0 | C11: 0.15 | D11: 0.155 | E11: 0.12 | F11: Booking 15% (din rezervările 6131205469, 5429915812, 6470558532). Airbnb: taxă unică gazdă 15,5% (editor Airbnb: 1.480 lei → câștigi 1.251 lei). Travelminit: „Nivelul de comisionare actual 12%” (admin → Îmbunătățirea poziției).
A12: Costuri procesare plată | B12: 0 | C12: 0.014 | D12: 0 | E12: 0 | F12: Booking „Comision și costuri” = ~16,4% din suma comisionabilă → ~1,4% Plăți prin Booking.com. Site: 0 la transfer bancar (pune % dacă încasezi cu cardul).
A13: Comision calculat fără taxele locale? (1=da, 0=nu) | B13: 1 | C13: 1 | D13: 0 | E13: 0 | F13: Booking scade taxa turistică + Salvamont din suma comisionabilă (ex. 1.458 lei total → 1.362 lei comisionabil). Airbnb/Travelminit: presupus pe tot prețul.
A14: Reducere automată a platformei | B14: 0 | C14: 0.1 | D14: 0 | E14: 0 | F14: Booking: „Mobile rate 10%” activ din 07.06.2026 – oaspeții de pe telefon primesc -10%. Pune 0 dacă o dezactivezi.
A15: Compensez reducerea automată în preț? (1=da, 0=nu) | B15: 0 | C15: 1 | D15: 1 | E15: 1 | F15: 1 = prețul de pe platformă e ridicat astfel încât și după reducerea de mobil câștigul net să fie același.
A16: Rotunjire în sus la (lei) | B16: 10 | C16: 10 | D16: 10 | E16: 10 | F16: Prețurile calculate se rotunjesc în sus la multiplu de 10 lei.
A17: Aplică reducerile pe durată din „Sezoane”? (1=da, 0=nu) | B17: 1 | C17: 1 | D17: 0 | E17: 0 | F17: Booking are planurile „2 zile -10%” … „7 zile -33%” legate de Standard Rate. Airbnb are doar reducere săptămânală/lunară; Travelminit – nu are setate.
A19: Airbnb – reduceri pe durată (globale)
A20: Reducere săptămânală (7+ nopți) | B20: 0.33 | C20: Azi pe Airbnb: 32% săptămânal, 33% lunar. Recomandat: la fel ca site-ul la 7+ nopți (33%).
A21: Reducere lunară (28+ nopți) | B21: 0.33
A23: Comision efectiv total (calculat) | B23: =1-(1-B11)*(1-B12) -> 0 | C23: =1-(1-C11)*(1-C12) -> 0.1619 | D23: =1-(1-D11)*(1-D12) -> 0.155 | E23: =1-(1-E11)*(1-E12) -> 0.12
A25: Airbnb – cât ții cont de sugestiile Airbnb
A26: Pondere sugestie Airbnb (0% = net egal, 100% = exact sugestia) | B26: 0.3 | C26: Prețul Airbnb = amestec între prețul cu net egal și sugestia din „Sezoane” (coloana O). Se aplică doar sezoanelor cu sugestie completată.
A27: Câștig net minim pe Airbnb (% din netul de pe site) | B27: 0.85 | C27: Plasă de siguranță: prețul Airbnb nu coboară sub nivelul la care ai câștiga mai puțin de atât.
A28: Reducere „Rezervări de ultim moment” (0–14 zile) | B28: 0.15 | C28: Recomandat ca răspuns la sugestia Airbnb: prețul rămâne cu net egal când rezervă din timp, și scade doar pentru nopțile încă libere cu 14 zile înainte.
A30: Strategie câștig pe site
A31: Câștig net pe site mai mare decât pe platforme cu | B31: 0.05 | C31: Ex. 5%: dacă pe site câștigi 1.202 lei/noapte, pe platforme prețul e calculat să-ți rămână 1.202 / 1,05 = 1.145 lei. 0% = câștig egal peste tot.

Sheet Prețuri de setat
A1: Prețuri de setat pe fiecare platformă
A2: Calculat din „Sezoane” + „Platforme”. Net egal pe toate canalele; pe site oaspetele plătește cel mai puțin. Coloanele „Acum” = ce e setat azi (21.10.2026); roșu = diferă de recomandare.
A4: ID sezon | B4: De la | C4: Până la | D4: Nopți min. | E4: SITE tarif / noapte | F4: BOOKING Standard Rate | G4: AIRBNB preț / noapte | H4: TRAVELMINIT preț / noapte | I4: Câștig net SITE / noapte | J4: Booking pe mobil (plătește oaspetele) | K4: Site mai ieftin decât cea mai ieftină platformă | L4: Booking ACUM | M4: Airbnb ACUM | N4: Travelminit ACUM | O4: Politică anulare | P4: Sugestie Airbnb | Q4: Câștig net Airbnb | R4: Airbnb față de netul platformelor | S4: Airbnb ultim moment (preț) | T4: Câștig net ultim moment | U4: Câștig net Booking / Travelminit
A5: =IF(Sezoane!$A$6="","",Sezoane!A6) -> vara-toamna-2026 | B5: =IF(Sezoane!$A$6="","",Sezoane!C6) -> 46204 | C5: =IF(Sezoane!$A$6="","",Sezoane!D6) -> 46356 | D5: =IF(Sezoane!$A$6="","",Sezoane!F6) -> 2 | E5: =IF(Sezoane!$A$6="","",Sezoane!E6) -> 900 | F5: =IF(Sezoane!$A$6="","",CEILING(IF(Platforme!$C$13=1,(((Sezoane!E6-Platforme!$B$8)*(1-(Platforme!$B$11+Platforme!$B$12-Platforme!$B$11*Platforme!$B$12))*1/(1+Platforme!$B$31))/(1-(Platforme!$C$11+Platforme!$C$12-Platforme!$C$11*Platforme!$C$12))+Platforme!$B$8)/(1-(Platforme!$C$14*Platforme!$C$15)),(((Sezoane!E6-Platforme!$B$8)*(1-(Platforme!$B$11+Platforme!$B$12-Platforme!$B$11*Platforme!$B$12))*1/(1+Platforme!$B$31))+Platforme!$B$8)/((1-(Platforme!$C$11+Platforme!$C$12-Platforme!$C$11*Platforme!$C$12))*(1-(Platforme!$C$14*Platforme!$C$15)))),Platforme!$C$16)) -> 1130 | G5: =IF(Sezoane!$A$6="","",IF(N(Sezoane!O6)=0,CEILING(IF(Platforme!$D$13=1,(((Sezoane!E6-Platforme!$B$8)*(1-(Platforme!$B$11+Platforme!$B$12-Platforme!$B$11*Platforme!$B$12))*1/(1+Platforme!$B$31))/(1-(Platforme!$D$11+Platforme!$D$12-Platforme!$D$11*Platforme!$D$12))+Platforme!$B$8)/(1-(Platforme!$D$14*Platforme!$D$15)),(((Sezoane!E6-Platforme!$B$8)*(1-(Platforme!$B$11+Platforme!$B$12-Platforme!$B$11*Platforme!$B$12))*1/(1+Platforme!$B$31))+Platforme!$B$8)/((1-(Platforme!$D$11+Platforme!$D$12-Platforme!$D$11*Platforme!$D$12))*(1-(Platforme!$D$14*Platforme!$D$15)))),Platforme!$D$16),MAX(CEILING(IF(Platforme!$D$13=1,(((Sezoane!E6-Platforme!$B$8)*(1-(Platforme!$B$11+Platforme!$B$12-Platforme!$B$11*Platforme!$B$12))*Platforme!$B$27*(1+Platforme!$B$31)/(1+Platforme!$B$31))/(1-(Platforme!$D$11+Platforme!$D$12-Platforme!$D$11*Platforme!$D$12))+Platforme!$B$8)/(1-(Platforme!$D$14*Platforme!$D$15)),(((Sezoane!E6-Platforme!$B$8)*(1-(Platforme!$B$11+Platforme!$B$12-Platforme!$B$11*Platforme!$B$12))*Platforme!$B$27*(1+Platforme!$B$31)/(1+Platforme!$B$31))+Platforme!$B$8)/((1-(Platforme!$D$11+Platforme!$D$12-Platforme!$D$11*Platforme!$D$12))*(1-(Platforme!$D$14*Platforme!$D$15)))),Platforme!$D$16),CEILING(CEILING(IF(Platforme!$D$13=1,(((Sezoane!E6-Platforme!$B$8)*(1-(Platforme!$B$11+Platforme!$B$12-Platforme!$B$11*Platforme!$B$12))*1/(1+Platforme!$B$31))/(1-(Platforme!$D$11+Platforme!$D$12-Platforme!$D$11*Platforme!$D$12))+Platforme!$B$8)/(1-(Platforme!$D$14*Platforme!$D$15)),(((Sezoane!E6-Platforme!$B$8)*(1-(Platforme!$B$11+Platforme!$B$12-Platforme!$B$11*Platforme!$B$12))*1/(1+Platforme!$B$31))+Platforme!$B$8)/((1-(Platforme!$D$11+Platforme!$D$12-Platforme!$D$11*Platforme!$D$12))*(1-(Platforme!$D$14*Platforme!$D$15)))),Platforme!$D$16)*(1-Platforme!$B$26)+Sezoane!O6*Platforme!$B$26,Platforme!$D$16)))) -> 920 | H5: =IF(Sezoane!$A$6="","",CEILING(IF(Platforme!$E$13=1,(((Sezoane!E6-Platforme!$B$8)*(1-(Platforme!$B$11+Platforme!$B$12-Platforme!$B$11*Platforme!$B$12))*1/(1+Platforme!$B$31))/(1-(Platforme!$E$11+Platforme!$E$12-Platforme!$E$11*Platforme!$E$12))+Platforme!$B$8)/(1-(Platforme!$E$14*Platforme!$E$15)),(((Sezoane!E6-Platforme!$B$8)*(1-(Platforme!$B$11+Platforme!$B$12-Platforme!$B$11*Platforme!$B$12))*1/(1+Platforme!$B$31))+Platforme!$B$8)/((1-(Platforme!$E$11+Platforme!$E$12-Platforme!$E$11*Platforme!$E$12))*(1-(Platforme!$E$14*Platforme!$E$15)))),Platforme!$E$16)) -> 980 | I5: =IF(Sezoane!$A$6="","",(Sezoane!E6-Platforme!$B$8)*(1-(Platforme!$B$11+Platforme!$B$12-Platforme!$B$11*Platforme!$B$12))) -> 852 | J5: =IF(Sezoane!$A$6="","",F5*(1-Platforme!$C$14)) -> 1017 | K5: =IF(Sezoane!$A$6="","",1-E5/MIN(J5,G5,H5)) -> 0.02173913 | L5: =IF(Sezoane!$A$6="","",IFERROR(INDEX('Date actuale'!$C$6:$C$40,MATCH(A5,'Date actuale'!$A$6:$A$40,0)),"")) -> 1130 | M5: =IF(Sezoane!$A$6="","",IFERROR(INDEX('Date actuale'!$D$6:$D$40,MATCH(A5,'Date actuale'!$A$6:$A$40,0)),"")) -> 920 | N5: =IF(Sezoane!$A$6="","",IFERROR(INDEX('Date actuale'!$E$6:$E$40,MATCH(A5,'Date actuale'!$A$6:$A$40,0)),"")) -> 980 | O5: =IF(Sezoane!$A$6="","",Sezoane!M6) -> Flexibil 14 zile | P5: =IF(OR(Sezoane!$A$6="",N(Sezoane!O6)=0),"",Sezoane!O6) -> 474 | Q5: =IF(Sezoane!$A$6="","",IF(Platforme!$D$13=1,(G5*(1-Platforme!$D$14)-Platforme!$B$8)*(1-(Platforme!$D$11+Platforme!$D$12-Platforme!$D$11*Platforme!$D$12)),G5*(1-Platforme!$D$14)*(1-(Platforme!$D$11+Platforme!$D$12-Platforme!$D$11*Platforme!$D$12))-Platforme!$B$8)) -> 729.4 | R5: =IF(Sezoane!$A$6="","",Q5/U5-1) -> -0.10109155 | S5: =IF(Sezoane!$A$6="","",G5*(1-Platforme!$B$28)) -> 782 | T5: =IF(Sezoane!$A$6="","",IF(Platforme!$D$13=1,(S5*(1-Platforme!$D$14)-Platforme!$B$8)*(1-(Platforme!$D$11+Platforme!$D$12-Platforme!$D$11*Platforme!$D$12)),S5*(1-Platforme!$D$14)*(1-(Platforme!$D$11+Platforme!$D$12-Platforme!$D$11*Platforme!$D$12))-Platforme!$B$8)) -> 612.79 | U5: =IF(Sezoane!$A$6="","",I5/(1+Platforme!$B$31)) -> 811.42857
A6: =IF(Sezoane!$A$7="","",Sezoane!A7) -> iarna-2026 | B6: =IF(Sezoane!$A$7="","",Sezoane!C7) -> 46357 | C6: =IF(Sezoane!$A$7="","",Sezoane!D7) -> 46376 | D6: =IF(Sezoane!$A$7="","",Sezoane!F7) -> 2 | E6: =IF(Sezoane!$A$7="","",Sezoane!E7) -> 1250 | F6: =IF(Sezoane!$A$7="","",CEILING(IF(Platforme!$C$13=1,(((Sezoane!E7-Platforme!$B$8)*(1-(Platforme!$B$11+Platforme!$B$12-Platforme!$B$11*Platforme!$B$12))*1/(1+Platforme!$B$31))/(1-(Platforme!$C$11+Platforme!$C$12-Platforme!$C$11*Platforme!$C$12))+Platforme!$B$8)/(1-(Platforme!$C$14*Platforme!$C$15)),(((Sezoane!E7-Platforme!$B$8)*(1-(Platforme!$B$11+Platforme!$B$12-Platforme!$B$11*Platforme!$B$12))*1/(1+Platforme!$B$31))+Platforme!$B$8)/((1-(Platforme!$C$11+Platforme!$C$12-Platforme!$C$11*Platforme!$C$12))*(1-(Platforme!$C$14*Platforme!$C$15)))),Platforme!$C$16)) -> 1580 | G6: =IF(Sezoane!$A$7="","",IF(N(Sezoane!O7)=0,CEILING(IF(Platforme!$D$13=1,(((Sezoane!E7-Platforme!$B$8)*(1-(Platforme!$B$11+Platforme!$B$12-Platforme!$B$11*Platforme!$B$12))*1/(1+Platforme!$B$31))/(1-(Platforme!$D$11+Platforme!$D$12-Platforme!$D$11*Platforme!$D$12))+Platforme!$B$8)/(1-(Platforme!$D$14*Platforme!$D$15)),(((Sezoane!E7-Platforme!$B$8)*(1-(Platforme!$B$11+Platforme!$B$12-Platforme!$B$11*Platforme!$B$12))*1/(1+Platforme!$B$31))+Platforme!$B$8)/((1-(Platforme!$D$11+Platforme!$D$12-Platforme!$D$11*Platforme!$D$12))*(1-(Platforme!$D$14*Platforme!$D$15)))),Platforme!$D$16),MAX(CEILING(IF(Platforme!$D$13=1,(((Sezoane!E7-Platforme!$B$8)*(1-(Platforme!$B$11+Platforme!$B$12-Platforme!$B$11*Platforme!$B$12))*Platforme!$B$27*(1+Platforme!$B$31)/(1+Platforme!$B$31))/(1-(Platforme!$D$11+Platforme!$D$12-Platforme!$D$11*Platforme!$D$12))+Platforme!$B$8)/(1-(Platforme!$D$14*Platforme!$D$15)),(((Sezoane!E7-Platforme!$B$8)*(1-(Platforme!$B$11+Platforme!$B$12-Platforme!$B$11*Platforme!$B$12))*Platforme!$B$27*(1+Platforme!$B$31)/(1+Platforme!$B$31))+Platforme!$B$8)/((1-(Platforme!$D$11+Platforme!$D$12-Platforme!$D$11*Platforme!$D$12))*(1-(Platforme!$D$14*Platforme!$D$15)))),Platforme!$D$16),CEILING(CEILING(IF(Platforme!$D$13=1,(((Sezoane!E7-Platforme!$B$8)*(1-(Platforme!$B$11+Platforme!$B$12-Platforme!$B$11*Platforme!$B$12))*1/(1+Platforme!$B$31))/(1-(Platforme!$D$11+Platforme!$D$12-Platforme!$D$11*Platforme!$D$12))+Platforme!$B$8)/(1-(Platforme!$D$14*Platforme!$D$15)),(((Sezoane!E7-Platforme!$B$8)*(1-(Platforme!$B$11+Platforme!$B$12-Platforme!$B$11*Platforme!$B$12))*1/(1+Platforme!$B$31))+Platforme!$B$8)/((1-(Platforme!$D$11+Platforme!$D$12-Platforme!$D$11*Platforme!$D$12))*(1-(Platforme!$D$14*Platforme!$D$15)))),Platforme!$D$16)*(1-Platforme!$B$26)+Sezoane!O7*Platforme!$B$26,Platforme!$D$16)))) -> 1420 | H6: =IF(Sezoane!$A$7="","",CEILING(IF(Platforme!$E$13=1,(((Sezoane!E7-Platforme!$B$8)*(1-(Platforme!$B$11+Platforme!$B$12-Platforme!$B$11*Platforme!$B$12))*1/(1+Platforme!$B$31))/(1-(Platforme!$E$11+Platforme!$E$12-Platforme!$E$11*Platforme!$E$12))+Platforme!$B$8)/(1-(Platforme!$E$14*Platforme!$E$15)),(((Sezoane!E7-Platforme!$B$8)*(1-(Platforme!$B$11+Platforme!$B$12-Platforme!$B$11*Platforme!$B$12))*1/(1+Platforme!$B$31))+Platforme!$B$8)/((1-(Platforme!$E$11+Platforme!$E$12-Platforme!$E$11*Platforme!$E$12))*(1-(Platforme!$E$14*Platforme!$E$15)))),Platforme!$E$16)) -> 1360 | I6: =IF(Sezoane!$A$7="","",(Sezoane!E7-Platforme!$B$8)*(1-(Platforme!$B$11+Platforme!$B$12-Platforme!$B$11*Platforme!$B$12))) -> 1202 | J6: =IF(Sezoane!$A$7="","",F6*(1-Platforme!$C$14)) -> 1422 | K6: =IF(Sezoane!$A$7="","",1-E6/MIN(J6,G6,H6)) -> 0.080882353 | L6: =IF(Sezoane!$A$7="","",IFERROR(INDEX('Date actuale'!$C$6:$C$40,MATCH(A6,'Date actuale'!$A$6:$A$40,0)),"")) -> 1580 | M6: =IF(Sezoane!$A$7="","",IFERROR(INDEX('Date actuale'!$D$6:$D$40,MATCH(A6,'Date actuale'!$A$6:$A$40,0)),"")) -> 1420 | N6: =IF(Sezoane!$A$7="","",IFERROR(INDEX('Date actuale'!$E$6:$E$40,MATCH(A6,'Date actuale'!$A$6:$A$40,0)),"")) -> 1360 | O6: =IF(Sezoane!$A$7="","",Sezoane!M7) -> Flexibil 14 zile | P6: =IF(OR(Sezoane!$A$7="",N(Sezoane!O7)=0),"",Sezoane!O7) | Q6: =IF(Sezoane!$A$7="","",IF(Platforme!$D$13=1,(G6*(1-Platforme!$D$14)-Platforme!$B$8)*(1-(Platforme!$D$11+Platforme!$D$12-Platforme!$D$11*Platforme!$D$12)),G6*(1-Platforme!$D$14)*(1-(Platforme!$D$11+Platforme!$D$12-Platforme!$D$11*Platforme!$D$12))-Platforme!$B$8)) -> 1151.9 | R6: =IF(Sezoane!$A$7="","",Q6/U6-1) -> 0.0062354409 | S6: =IF(Sezoane!$A$7="","",G6*(1-Platforme!$B$28)) -> 1207 | T6: =IF(Sezoane!$A$7="","",IF(Platforme!$D$13=1,(S6*(1-Platforme!$D$14)-Platforme!$B$8)*(1-(Platforme!$D$11+Platforme!$D$12-Platforme!$D$11*Platforme!$D$12)),S6*(1-Platforme!$D$14)*(1-(Platforme!$D$11+Platforme!$D$12-Platforme!$D$11*Platforme!$D$12))-Platforme!$B$8)) -> 971.915 | U6: =IF(Sezoane!$A$7="","",I6/(1+Platforme!$B$31)) -> 1144.7619
A7: =IF(Sezoane!$A$8="","",Sezoane!A8) -> Craciun-2026 | B7: =IF(Sezoane!$A$8="","",Sezoane!C8) -> 46377 | C7: =IF(Sezoane!$A$8="","",Sezoane!D8) -> 46383 | D7: =IF(Sezoane!$A$8="","",Sezoane!F8) -> 3 | E7: =IF(Sezoane!$A$8="","",Sezoane!E8) -> 1500 | F7: =IF(Sezoane!$A$8="","",CEILING(IF(Platforme!$C$13=1,(((Sezoane!E8-Platforme!$B$8)*(1-(Platforme!$B$11+Platforme!$B$12-Platforme!$B$11*Platforme!$B$12))*1/(1+Platforme!$B$31))/(1-(Platforme!$C$11+Platforme!$C$12-Platforme!$C$11*Platforme!$C$12))+Platforme!$B$8)/(1-(Platforme!$C$14*Platforme!$C$15)),(((Sezoane!E8-Platforme!$B$8)*(1-(Platforme!$B$11+Platforme!$B$12-Platforme!$B$11*Platforme!$B$12))*1/(1+Platforme!$B$31))+Platforme!$B$8)/((1-(Platforme!$C$11+Platforme!$C$12-Platforme!$C$11*Platforme!$C$12))*(1-(Platforme!$C$14*Platforme!$C$15)))),Platforme!$C$16)) -> 1890 | G7: =IF(Sezoane!$A$8="","",IF(N(Sezoane!O8)=0,CEILING(IF(Platforme!$D$13=1,(((Sezoane!E8-Platforme!$B$8)*(1-(Platforme!$B$11+Platforme!$B$12-Platforme!$B$11*Platforme!$B$12))*1/(1+Platforme!$B$31))/(1-(Platforme!$D$11+Platforme!$D$12-Platforme!$D$11*Platforme!$D$12))+Platforme!$B$8)/(1-(Platforme!$D$14*Platforme!$D$15)),(((Sezoane!E8-Platforme!$B$8)*(1-(Platforme!$B$11+Platforme!$B$12-Platforme!$B$11*Platforme!$B$12))*1/(1+Platforme!$B$31))+Platforme!$B$8)/((1-(Platforme!$D$11+Platforme!$D$12-Platforme!$D$11*Platforme!$D$12))*(1-(Platforme!$D$14*Platforme!$D$15)))),Platforme!$D$16),MAX(CEILING(IF(Platforme!$D$13=1,(((Sezoane!E8-Platforme!$B$8)*(1-(Platforme!$B$11+Platforme!$B$12-Platforme!$B$11*Platforme!$B$12))*Platforme!$B$27*(1+Platforme!$B$31)/(1+Platforme!$B$31))/(1-(Platforme!$D$11+Platforme!$D$12-Platforme!$D$11*Platforme!$D$12))+Platforme!$B$8)/(1-(Platforme!$D$14*Platforme!$D$15)),(((Sezoane!E8-Platforme!$B$8)*(1-(Platforme!$B$11+Platforme!$B$12-Platforme!$B$11*Platforme!$B$12))*Platforme!$B$27*(1+Platforme!$B$31)/(1+Platforme!$B$31))+Platforme!$B$8)/((1-(Platforme!$D$11+Platforme!$D$12-Platforme!$D$11*Platforme!$D$12))*(1-(Platforme!$D$14*Platforme!$D$15)))),Platforme!$D$16),CEILING(CEILING(IF(Platforme!$D$13=1,(((Sezoane!E8-Platforme!$B$8)*(1-(Platforme!$B$11+Platforme!$B$12-Platforme!$B$11*Platforme!$B$12))*1/(1+Platforme!$B$31))/(1-(Platforme!$D$11+Platforme!$D$12-Platforme!$D$11*Platforme!$D$12))+Platforme!$B$8)/(1-(Platforme!$D$14*Platforme!$D$15)),(((Sezoane!E8-Platforme!$B$8)*(1-(Platforme!$B$11+Platforme!$B$12-Platforme!$B$11*Platforme!$B$12))*1/(1+Platforme!$B$31))+Platforme!$B$8)/((1-(Platforme!$D$11+Platforme!$D$12-Platforme!$D$11*Platforme!$D$12))*(1-(Platforme!$D$14*Platforme!$D$15)))),Platforme!$D$16)*(1-Platforme!$B$26)+Sezoane!O8*Platforme!$B$26,Platforme!$D$16)))) -> 1700 | H7: =IF(Sezoane!$A$8="","",CEILING(IF(Platforme!$E$13=1,(((Sezoane!E8-Platforme!$B$8)*(1-(Platforme!$B$11+Platforme!$B$12-Platforme!$B$11*Platforme!$B$12))*1/(1+Platforme!$B$31))/(1-(Platforme!$E$11+Platforme!$E$12-Platforme!$E$11*Platforme!$E$12))+Platforme!$B$8)/(1-(Platforme!$E$14*Platforme!$E$15)),(((Sezoane!E8-Platforme!$B$8)*(1-(Platforme!$B$11+Platforme!$B$12-Platforme!$B$11*Platforme!$B$12))*1/(1+Platforme!$B$31))+Platforme!$B$8)/((1-(Platforme!$E$11+Platforme!$E$12-Platforme!$E$11*Platforme!$E$12))*(1-(Platforme!$E$14*Platforme!$E$15)))),Platforme!$E$16)) -> 1630 | I7: =IF(Sezoane!$A$8="","",(Sezoane!E8-Platforme!$B$8)*(1-(Platforme!$B$11+Platforme!$B$12-Platforme!$B$11*Platforme!$B$12))) -> 1452 | J7: =IF(Sezoane!$A$8="","",F7*(1-Platforme!$C$14)) -> 1701 | K7: =IF(Sezoane!$A$8="","",1-E7/MIN(J7,G7,H7)) -> 0.079754601 | L7: =IF(Sezoane!$A$8="","",IFERROR(INDEX('Date actuale'!$C$6:$C$40,MATCH(A7,'Date actuale'!$A$6:$A$40,0)),"")) -> 1500 | M7: =IF(Sezoane!$A$8="","",IFERROR(INDEX('Date actuale'!$D$6:$D$40,MATCH(A7,'Date actuale'!$A$6:$A$40,0)),"")) -> 1700 | N7: =IF(Sezoane!$A$8="","",IFERROR(INDEX('Date actuale'!$E$6:$E$40,MATCH(A7,'Date actuale'!$A$6:$A$40,0)),"")) -> 1700 | O7: =IF(Sezoane!$A$8="","",Sezoane!M8) -> Nerambursabil | P7: =IF(OR(Sezoane!$A$8="",N(Sezoane!O8)=0),"",Sezoane!O8) | Q7: =IF(Sezoane!$A$8="","",IF(Platforme!$D$13=1,(G7*(1-Platforme!$D$14)-Platforme!$B$8)*(1-(Platforme!$D$11+Platforme!$D$12-Platforme!$D$11*Platforme!$D$12)),G7*(1-Platforme!$D$14)*(1-(Platforme!$D$11+Platforme!$D$12-Platforme!$D$11*Platforme!$D$12))-Platforme!$B$8)) -> 1388.5 | R7: =IF(Sezoane!$A$8="","",Q7/U7-1) -> 0.0040805785 | S7: =IF(Sezoane!$A$8="","",G7*(1-Platforme!$B$28)) -> 1445 | T7: =IF(Sezoane!$A$8="","",IF(Platforme!$D$13=1,(S7*(1-Platforme!$D$14)-Platforme!$B$8)*(1-(Platforme!$D$11+Platforme!$D$12-Platforme!$D$11*Platforme!$D$12)),S7*(1-Platforme!$D$14)*(1-(Platforme!$D$11+Platforme!$D$12-Platforme!$D$11*Platforme!$D$12))-Platforme!$B$8)) -> 1173.025 | U7: =IF(Sezoane!$A$8="","",I7/(1+Platforme!$B$31)) -> 1382.8571
A8: =IF(Sezoane!$A$9="","",Sezoane!A9) -> Revelion-2026-2027 | B8: =IF(Sezoane!$A$9="","",Sezoane!C9) -> 46384 | C8: =IF(Sezoane!$A$9="","",Sezoane!D9) -> 46391 | D8: =IF(Sezoane!$A$9="","",Sezoane!F9) -> 4 | E8: =IF(Sezoane!$A$9="","",Sezoane!E9) -> 1800 | F8: =IF(Sezoane!$A$9="","",CEILING(IF(Platforme!$C$13=1,(((Sezoane!E9-Platforme!$B$8)*(1-(Platforme!$B$11+Platforme!$B$12-Platforme!$B$11*Platforme!$B$12))*1/(1+Platforme!$B$31))/(1-(Platforme!$C$11+Platforme!$C$12-Platforme!$C$11*Platforme!$C$12))+Platforme!$B$8)/(1-(Platforme!$C$14*Platforme!$C$15)),(((Sezoane!E9-Platforme!$B$8)*(1-(Platforme!$B$11+Platforme!$B$12-Platforme!$B$11*Platforme!$B$12))*1/(1+Platforme!$B$31))+Platforme!$B$8)/((1-(Platforme!$C$11+Platforme!$C$12-Platforme!$C$11*Platforme!$C$12))*(1-(Platforme!$C$14*Platforme!$C$15)))),Platforme!$C$16)) -> 2270 | G8: =IF(Sezoane!$A$9="","",IF(N(Sezoane!O9)=0,CEILING(IF(Platforme!$D$13=1,(((Sezoane!E9-Platforme!$B$8)*(1-(Platforme!$B$11+Platforme!$B$12-Platforme!$B$11*Platforme!$B$12))*1/(1+Platforme!$B$31))/(1-(Platforme!$D$11+Platforme!$D$12-Platforme!$D$11*Platforme!$D$12))+Platforme!$B$8)/(1-(Platforme!$D$14*Platforme!$D$15)),(((Sezoane!E9-Platforme!$B$8)*(1-(Platforme!$B$11+Platforme!$B$12-Platforme!$B$11*Platforme!$B$12))*1/(1+Platforme!$B$31))+Platforme!$B$8)/((1-(Platforme!$D$11+Platforme!$D$12-Platforme!$D$11*Platforme!$D$12))*(1-(Platforme!$D$14*Platforme!$D$15)))),Platforme!$D$16),MAX(CEILING(IF(Platforme!$D$13=1,(((Sezoane!E9-Platforme!$B$8)*(1-(Platforme!$B$11+Platforme!$B$12-Platforme!$B$11*Platforme!$B$12))*Platforme!$B$27*(1+Platforme!$B$31)/(1+Platforme!$B$31))/(1-(Platforme!$D$11+Platforme!$D$12-Platforme!$D$11*Platforme!$D$12))+Platforme!$B$8)/(1-(Platforme!$D$14*Platforme!$D$15)),(((Sezoane!E9-Platforme!$B$8)*(1-(Platforme!$B$11+Platforme!$B$12-Platforme!$B$11*Platforme!$B$12))*Platforme!$B$27*(1+Platforme!$B$31)/(1+Platforme!$B$31))+Platforme!$B$8)/((1-(Platforme!$D$11+Platforme!$D$12-Platforme!$D$11*Platforme!$D$12))*(1-(Platforme!$D$14*Platforme!$D$15)))),Platforme!$D$16),CEILING(CEILING(IF(Platforme!$D$13=1,(((Sezoane!E9-Platforme!$B$8)*(1-(Platforme!$B$11+Platforme!$B$12-Platforme!$B$11*Platforme!$B$12))*1/(1+Platforme!$B$31))/(1-(Platforme!$D$11+Platforme!$D$12-Platforme!$D$11*Platforme!$D$12))+Platforme!$B$8)/(1-(Platforme!$D$14*Platforme!$D$15)),(((Sezoane!E9-Platforme!$B$8)*(1-(Platforme!$B$11+Platforme!$B$12-Platforme!$B$11*Platforme!$B$12))*1/(1+Platforme!$B$31))+Platforme!$B$8)/((1-(Platforme!$D$11+Platforme!$D$12-Platforme!$D$11*Platforme!$D$12))*(1-(Platforme!$D$14*Platforme!$D$15)))),Platforme!$D$16)*(1-Platforme!$B$26)+Sezoane!O9*Platforme!$B$26,Platforme!$D$16)))) -> 2040 | H8: =IF(Sezoane!$A$9="","",CEILING(IF(Platforme!$E$13=1,(((Sezoane!E9-Platforme!$B$8)*(1-(Platforme!$B$11+Platforme!$B$12-Platforme!$B$11*Platforme!$B$12))*1/(1+Platforme!$B$31))/(1-(Platforme!$E$11+Platforme!$E$12-Platforme!$E$11*Platforme!$E$12))+Platforme!$B$8)/(1-(Platforme!$E$14*Platforme!$E$15)),(((Sezoane!E9-Platforme!$B$8)*(1-(Platforme!$B$11+Platforme!$B$12-Platforme!$B$11*Platforme!$B$12))*1/(1+Platforme!$B$31))+Platforme!$B$8)/((1-(Platforme!$E$11+Platforme!$E$12-Platforme!$E$11*Platforme!$E$12))*(1-(Platforme!$E$14*Platforme!$E$15)))),Platforme!$E$16)) -> 1960 | I8: =IF(Sezoane!$A$9="","",(Sezoane!E9-Platforme!$B$8)*(1-(Platforme!$B$11+Platforme!$B$12-Platforme!$B$11*Platforme!$B$12))) -> 1752 | J8: =IF(Sezoane!$A$9="","",F8*(1-Platforme!$C$14)) -> 2043 | K8: =IF(Sezoane!$A$9="","",1-E8/MIN(J8,G8,H8)) -> 0.081632653 | L8: =IF(Sezoane!$A$9="","",IFERROR(INDEX('Date actuale'!$C$6:$C$40,MATCH(A8,'Date actuale'!$A$6:$A$40,0)),"")) -> 1800 | M8: =IF(Sezoane!$A$9="","",IFERROR(INDEX('Date actuale'!$D$6:$D$40,MATCH(A8,'Date actuale'!$A$6:$A$40,0)),"")) -> 2000 | N8: =IF(Sezoane!$A$9="","",IFERROR(INDEX('Date actuale'!$E$6:$E$40,MATCH(A8,'Date actuale'!$A$6:$A$40,0)),"")) -> 2000 | O8: =IF(Sezoane!$A$9="","",Sezoane!M9) -> Nerambursabil | P8: =IF(OR(Sezoane!$A$9="",N(Sezoane!O9)=0),"",Sezoane!O9) | Q8: =IF(Sezoane!$A$9="","",IF(Platforme!$D$13=1,(G8*(1-Platforme!$D$14)-Platforme!$B$8)*(1-(Platforme!$D$11+Platforme!$D$12-Platforme!$D$11*Platforme!$D$12)),G8*(1-Platforme!$D$14)*(1-(Platforme!$D$11+Platforme!$D$12-Platforme!$D$11*Platforme!$D$12))-Platforme!$B$8)) -> 1675.8 | R8: =IF(Sezoane!$A$9="","",Q8/U8-1) -> 0.0043321918 | S8: =IF(Sezoane!$A$9="","",G8*(1-Platforme!$B$28)) -> 1734 | T8: =IF(Sezoane!$A$9="","",IF(Platforme!$D$13=1,(S8*(1-Platforme!$D$14)-Platforme!$B$8)*(1-(Platforme!$D$11+Platforme!$D$12-Platforme!$D$11*Platforme!$D$12)),S8*(1-Platforme!$D$14)*(1-(Platforme!$D$11+Platforme!$D$12-Platforme!$D$11*Platforme!$D$12))-Platforme!$B$8)) -> 1417.23 | U8: =IF(Sezoane!$A$9="","",I8/(1+Platforme!$B$31)) -> 1668.5714
A9: =IF(Sezoane!$A$10="","",Sezoane!A10) -> iarna-2027 | B9: =IF(Sezoane!$A$10="","",Sezoane!C10) -> 46392 | C9: =IF(Sezoane!$A$10="","",Sezoane!D10) -> 46432 | D9: =IF(Sezoane!$A$10="","",Sezoane!F10) -> 2 | E9: =IF(Sezoane!$A$10="","",Sezoane!E10) -> 1350 | F9: =IF(Sezoane!$A$10="","",CEILING(IF(Platforme!$C$13=1,(((Sezoane!E10-Platforme!$B$8)*(1-(Platforme!$B$11+Platforme!$B$12-Platforme!$B$11*Platforme!$B$12))*1/(1+Platforme!$B$31))/(1-(Platforme!$C$11+Platforme!$C$12-Platforme!$C$11*Platforme!$C$12))+Platforme!$B$8)/(1-(Platforme!$C$14*Platforme!$C$15)),(((Sezoane!E10-Platforme!$B$8)*(1-(Platforme!$B$11+Platforme!$B$12-Platforme!$B$11*Platforme!$B$12))*1/(1+Platforme!$B$31))+Platforme!$B$8)/((1-(Platforme!$C$11+Platforme!$C$12-Platforme!$C$11*Platforme!$C$12))*(1-(Platforme!$C$14*Platforme!$C$15)))),Platforme!$C$16)) -> 1700 | G9: =IF(Sezoane!$A$10="","",IF(N(Sezoane!O10)=0,CEILING(IF(Platforme!$D$13=1,(((Sezoane!E10-Platforme!$B$8)*(1-(Platforme!$B$11+Platforme!$B$12-Platforme!$B$11*Platforme!$B$12))*1/(1+Platforme!$B$31))/(1-(Platforme!$D$11+Platforme!$D$12-Platforme!$D$11*Platforme!$D$12))+Platforme!$B$8)/(1-(Platforme!$D$14*Platforme!$D$15)),(((Sezoane!E10-Platforme!$B$8)*(1-(Platforme!$B$11+Platforme!$B$12-Platforme!$B$11*Platforme!$B$12))*1/(1+Platforme!$B$31))+Platforme!$B$8)/((1-(Platforme!$D$11+Platforme!$D$12-Platforme!$D$11*Platforme!$D$12))*(1-(Platforme!$D$14*Platforme!$D$15)))),Platforme!$D$16),MAX(CEILING(IF(Platforme!$D$13=1,(((Sezoane!E10-Platforme!$B$8)*(1-(Platforme!$B$11+Platforme!$B$12-Platforme!$B$11*Platforme!$B$12))*Platforme!$B$27*(1+Platforme!$B$31)/(1+Platforme!$B$31))/(1-(Platforme!$D$11+Platforme!$D$12-Platforme!$D$11*Platforme!$D$12))+Platforme!$B$8)/(1-(Platforme!$D$14*Platforme!$D$15)),(((Sezoane!E10-Platforme!$B$8)*(1-(Platforme!$B$11+Platforme!$B$12-Platforme!$B$11*Platforme!$B$12))*Platforme!$B$27*(1+Platforme!$B$31)/(1+Platforme!$B$31))+Platforme!$B$8)/((1-(Platforme!$D$11+Platforme!$D$12-Platforme!$D$11*Platforme!$D$12))*(1-(Platforme!$D$14*Platforme!$D$15)))),Platforme!$D$16),CEILING(CEILING(IF(Platforme!$D$13=1,(((Sezoane!E10-Platforme!$B$8)*(1-(Platforme!$B$11+Platforme!$B$12-Platforme!$B$11*Platforme!$B$12))*1/(1+Platforme!$B$31))/(1-(Platforme!$D$11+Platforme!$D$12-Platforme!$D$11*Platforme!$D$12))+Platforme!$B$8)/(1-(Platforme!$D$14*Platforme!$D$15)),(((Sezoane!E10-Platforme!$B$8)*(1-(Platforme!$B$11+Platforme!$B$12-Platforme!$B$11*Platforme!$B$12))*1/(1+Platforme!$B$31))+Platforme!$B$8)/((1-(Platforme!$D$11+Platforme!$D$12-Platforme!$D$11*Platforme!$D$12))*(1-(Platforme!$D$14*Platforme!$D$15)))),Platforme!$D$16)*(1-Platforme!$B$26)+Sezoane!O10*Platforme!$B$26,Platforme!$D$16)))) -> 1530 | H9: =IF(Sezoane!$A$10="","",CEILING(IF(Platforme!$E$13=1,(((Sezoane!E10-Platforme!$B$8)*(1-(Platforme!$B$11+Platforme!$B$12-Platforme!$B$11*Platforme!$B$12))*1/(1+Platforme!$B$31))/(1-(Platforme!$E$11+Platforme!$E$12-Platforme!$E$11*Platforme!$E$12))+Platforme!$B$8)/(1-(Platforme!$E$14*Platforme!$E$15)),(((Sezoane!E10-Platforme!$B$8)*(1-(Platforme!$B$11+Platforme!$B$12-Platforme!$B$11*Platforme!$B$12))*1/(1+Platforme!$B$31))+Platforme!$B$8)/((1-(Platforme!$E$11+Platforme!$E$12-Platforme!$E$11*Platforme!$E$12))*(1-(Platforme!$E$14*Platforme!$E$15)))),Platforme!$E$16)) -> 1470 | I9: =IF(Sezoane!$A$10="","",(Sezoane!E10-Platforme!$B$8)*(1-(Platforme!$B$11+Platforme!$B$12-Platforme!$B$11*Platforme!$B$12))) -> 1302 | J9: =IF(Sezoane!$A$10="","",F9*(1-Platforme!$C$14)) -> 1530 | K9: =IF(Sezoane!$A$10="","",1-E9/MIN(J9,G9,H9)) -> 0.081632653 | L9: =IF(Sezoane!$A$10="","",IFERROR(INDEX('Date actuale'!$C$6:$C$40,MATCH(A9,'Date actuale'!$A$6:$A$40,0)),"")) -> 1350 | M9: =IF(Sezoane!$A$10="","",IFERROR(INDEX('Date actuale'!$D$6:$D$40,MATCH(A9,'Date actuale'!$A$6:$A$40,0)),"")) -> 1450 | N9: =IF(Sezoane!$A$10="","",IFERROR(INDEX('Date actuale'!$E$6:$E$40,MATCH(A9,'Date actuale'!$A$6:$A$40,0)),"")) -> 1450 | O9: =IF(Sezoane!$A$10="","",Sezoane!M10) -> Flexibil 14 zile | P9: =IF(OR(Sezoane!$A$10="",N(Sezoane!O10)=0),"",Sezoane!O10) | Q9: =IF(Sezoane!$A$10="","",IF(Platforme!$D$13=1,(G9*(1-Platforme!$D$14)-Platforme!$B$8)*(1-(Platforme!$D$11+Platforme!$D$12-Platforme!$D$11*Platforme!$D$12)),G9*(1-Platforme!$D$14)*(1-(Platforme!$D$11+Platforme!$D$12-Platforme!$D$11*Platforme!$D$12))-Platforme!$B$8)) -> 1244.85 | R9: =IF(Sezoane!$A$10="","",Q9/U9-1) -> 0.0039112903 | S9: =IF(Sezoane!$A$10="","",G9*(1-Platforme!$B$28)) -> 1300.5 | T9: =IF(Sezoane!$A$10="","",IF(Platforme!$D$13=1,(S9*(1-Platforme!$D$14)-Platforme!$B$8)*(1-(Platforme!$D$11+Platforme!$D$12-Platforme!$D$11*Platforme!$D$12)),S9*(1-Platforme!$D$14)*(1-(Platforme!$D$11+Platforme!$D$12-Platforme!$D$11*Platforme!$D$12))-Platforme!$B$8)) -> 1050.9225 | U9: =IF(Sezoane!$A$10="","",I9/(1+Platforme!$B$31)) -> 1240
A10: =IF(Sezoane!$A$11="","",Sezoane!A11) -> Vacanta-schi-2027 | B10: =IF(Sezoane!$A$11="","",Sezoane!C11) -> 46433 | C10: =IF(Sezoane!$A$11="","",Sezoane!D11) -> 46453 | D10: =IF(Sezoane!$A$11="","",Sezoane!F11) -> 2 | E10: =IF(Sezoane!$A$11="","",Sezoane!E11) -> 1450 | F10: =IF(Sezoane!$A$11="","",CEILING(IF(Platforme!$C$13=1,(((Sezoane!E11-Platforme!$B$8)*(1-(Platforme!$B$11+Platforme!$B$12-Platforme!$B$11*Platforme!$B$12))*1/(1+Platforme!$B$31))/(1-(Platforme!$C$11+Platforme!$C$12-Platforme!$C$11*Platforme!$C$12))+Platforme!$B$8)/(1-(Platforme!$C$14*Platforme!$C$15)),(((Sezoane!E11-Platforme!$B$8)*(1-(Platforme!$B$11+Platforme!$B$12-Platforme!$B$11*Platforme!$B$12))*1/(1+Platforme!$B$31))+Platforme!$B$8)/((1-(Platforme!$C$11+Platforme!$C$12-Platforme!$C$11*Platforme!$C$12))*(1-(Platforme!$C$14*Platforme!$C$15)))),Platforme!$C$16)) -> 1830 | G10: =IF(Sezoane!$A$11="","",IF(N(Sezoane!O11)=0,CEILING(IF(Platforme!$D$13=1,(((Sezoane!E11-Platforme!$B$8)*(1-(Platforme!$B$11+Platforme!$B$12-Platforme!$B$11*Platforme!$B$12))*1/(1+Platforme!$B$31))/(1-(Platforme!$D$11+Platforme!$D$12-Platforme!$D$11*Platforme!$D$12))+Platforme!$B$8)/(1-(Platforme!$D$14*Platforme!$D$15)),(((Sezoane!E11-Platforme!$B$8)*(1-(Platforme!$B$11+Platforme!$B$12-Platforme!$B$11*Platforme!$B$12))*1/(1+Platforme!$B$31))+Platforme!$B$8)/((1-(Platforme!$D$11+Platforme!$D$12-Platforme!$D$11*Platforme!$D$12))*(1-(Platforme!$D$14*Platforme!$D$15)))),Platforme!$D$16),MAX(CEILING(IF(Platforme!$D$13=1,(((Sezoane!E11-Platforme!$B$8)*(1-(Platforme!$B$11+Platforme!$B$12-Platforme!$B$11*Platforme!$B$12))*Platforme!$B$27*(1+Platforme!$B$31)/(1+Platforme!$B$31))/(1-(Platforme!$D$11+Platforme!$D$12-Platforme!$D$11*Platforme!$D$12))+Platforme!$B$8)/(1-(Platforme!$D$14*Platforme!$D$15)),(((Sezoane!E11-Platforme!$B$8)*(1-(Platforme!$B$11+Platforme!$B$12-Platforme!$B$11*Platforme!$B$12))*Platforme!$B$27*(1+Platforme!$B$31)/(1+Platforme!$B$31))+Platforme!$B$8)/((1-(Platforme!$D$11+Platforme!$D$12-Platforme!$D$11*Platforme!$D$12))*(1-(Platforme!$D$14*Platforme!$D$15)))),Platforme!$D$16),CEILING(CEILING(IF(Platforme!$D$13=1,(((Sezoane!E11-Platforme!$B$8)*(1-(Platforme!$B$11+Platforme!$B$12-Platforme!$B$11*Platforme!$B$12))*1/(1+Platforme!$B$31))/(1-(Platforme!$D$11+Platforme!$D$12-Platforme!$D$11*Platforme!$D$12))+Platforme!$B$8)/(1-(Platforme!$D$14*Platforme!$D$15)),(((Sezoane!E11-Platforme!$B$8)*(1-(Platforme!$B$11+Platforme!$B$12-Platforme!$B$11*Platforme!$B$12))*1/(1+Platforme!$B$31))+Platforme!$B$8)/((1-(Platforme!$D$11+Platforme!$D$12-Platforme!$D$11*Platforme!$D$12))*(1-(Platforme!$D$14*Platforme!$D$15)))),Platforme!$D$16)*(1-Platforme!$B$26)+Sezoane!O11*Platforme!$B$26,Platforme!$D$16)))) -> 1640 | H10: =IF(Sezoane!$A$11="","",CEILING(IF(Platforme!$E$13=1,(((Sezoane!E11-Platforme!$B$8)*(1-(Platforme!$B$11+Platforme!$B$12-Platforme!$B$11*Platforme!$B$12))*1/(1+Platforme!$B$31))/(1-(Platforme!$E$11+Platforme!$E$12-Platforme!$E$11*Platforme!$E$12))+Platforme!$B$8)/(1-(Platforme!$E$14*Platforme!$E$15)),(((Sezoane!E11-Platforme!$B$8)*(1-(Platforme!$B$11+Platforme!$B$12-Platforme!$B$11*Platforme!$B$12))*1/(1+Platforme!$B$31))+Platforme!$B$8)/((1-(Platforme!$E$11+Platforme!$E$12-Platforme!$E$11*Platforme!$E$12))*(1-(Platforme!$E$14*Platforme!$E$15)))),Platforme!$E$16)) -> 1580 | I10: =IF(Sezoane!$A$11="","",(Sezoane!E11-Platforme!$B$8)*(1-(Platforme!$B$11+Platforme!$B$12-Platforme!$B$11*Platforme!$B$12))) -> 1402 | J10: =IF(Sezoane!$A$11="","",F10*(1-Platforme!$C$14)) -> 1647 | K10: =IF(Sezoane!$A$11="","",1-E10/MIN(J10,G10,H10)) -> 0.082278481 | L10: =IF(Sezoane!$A$11="","",IFERROR(INDEX('Date actuale'!$C$6:$C$40,MATCH(A10,'Date actuale'!$A$6:$A$40,0)),"")) -> 1450 | M10: =IF(Sezoane!$A$11="","",IFERROR(INDEX('Date actuale'!$D$6:$D$40,MATCH(A10,'Date actuale'!$A$6:$A$40,0)),"")) -> 1500 | N10: =IF(Sezoane!$A$11="","",IFERROR(INDEX('Date actuale'!$E$6:$E$40,MATCH(A10,'Date actuale'!$A$6:$A$40,0)),"")) -> 1500 | O10: =IF(Sezoane!$A$11="","",Sezoane!M11) -> Flexibil 14 zile | P10: =IF(OR(Sezoane!$A$11="",N(Sezoane!O11)=0),"",Sezoane!O11) | Q10: =IF(Sezoane!$A$11="","",IF(Platforme!$D$13=1,(G10*(1-Platforme!$D$14)-Platforme!$B$8)*(1-(Platforme!$D$11+Platforme!$D$12-Platforme!$D$11*Platforme!$D$12)),G10*(1-Platforme!$D$14)*(1-(Platforme!$D$11+Platforme!$D$12-Platforme!$D$11*Platforme!$D$12))-Platforme!$B$8)) -> 1337.8 | R10: =IF(Sezoane!$A$11="","",Q10/U10-1) -> 0.0019186876 | S10: =IF(Sezoane!$A$11="","",G10*(1-Platforme!$B$28)) -> 1394 | T10: =IF(Sezoane!$A$11="","",IF(Platforme!$D$13=1,(S10*(1-Platforme!$D$14)-Platforme!$B$8)*(1-(Platforme!$D$11+Platforme!$D$12-Platforme!$D$11*Platforme!$D$12)),S10*(1-Platforme!$D$14)*(1-(Platforme!$D$11+Platforme!$D$12-Platforme!$D$11*Platforme!$D$12))-Platforme!$B$8)) -> 1129.93 | U10: =IF(Sezoane!$A$11="","",I10/(1+Platforme!$B$31)) -> 1335.2381
A11: =IF(Sezoane!$A$12="","",Sezoane!A12) | B11: =IF(Sezoane!$A$12="","",Sezoane!C12) | C11: =IF(Sezoane!$A$12="","",Sezoane!D12) | D11: =IF(Sezoane!$A$12="","",Sezoane!F12) | E11: =IF(Sezoane!$A$12="","",Sezoane!E12) | F11: =IF(Sezoane!$A$12="","",CEILING(IF(Platforme!$C$13=1,(((Sezoane!E12-Platforme!$B$8)*(1-(Platforme!$B$11+Platforme!$B$12-Platforme!$B$11*Platforme!$B$12))*1/(1+Platforme!$B$31))/(1-(Platforme!$C$11+Platforme!$C$12-Platforme!$C$11*Platforme!$C$12))+Platforme!$B$8)/(1-(Platforme!$C$14*Platforme!$C$15)),(((Sezoane!E12-Platforme!$B$8)*(1-(Platforme!$B$11+Platforme!$B$12-Platforme!$B$11*Platforme!$B$12))*1/(1+Platforme!$B$31))+Platforme!$B$8)/((1-(Platforme!$C$11+Platforme!$C$12-Platforme!$C$11*Platforme!$C$12))*(1-(Platforme!$C$14*Platforme!$C$15)))),Platforme!$C$16)) | G11: =IF(Sezoane!$A$12="","",IF(N(Sezoane!O12)=0,CEILING(IF(Platforme!$D$13=1,(((Sezoane!E12-Platforme!$B$8)*(1-(Platforme!$B$11+Platforme!$B$12-Platforme!$B$11*Platforme!$B$12))*1/(1+Platforme!$B$31))/(1-(Platforme!$D$11+Platforme!$D$12-Platforme!$D$11*Platforme!$D$12))+Platforme!$B$8)/(1-(Platforme!$D$14*Platforme!$D$15)),(((Sezoane!E12-Platforme!$B$8)*(1-(Platforme!$B$11+Platforme!$B$12-Platforme!$B$11*Platforme!$B$12))*1/(1+Platforme!$B$31))+Platforme!$B$8)/((1-(Platforme!$D$11+Platforme!$D$12-Platforme!$D$11*Platforme!$D$12))*(1-(Platforme!$D$14*Platforme!$D$15)))),Platforme!$D$16),MAX(CEILING(IF(Platforme!$D$13=1,(((Sezoane!E12-Platforme!$B$8)*(1-(Platforme!$B$11+Platforme!$B$12-Platforme!$B$11*Platforme!$B$12))*Platforme!$B$27*(1+Platforme!$B$31)/(1+Platforme!$B$31))/(1-(Platforme!$D$11+Platforme!$D$12-Platforme!$D$11*Platforme!$D$12))+Platforme!$B$8)/(1-(Platforme!$D$14*Platforme!$D$15)),(((Sezoane!E12-Platforme!$B$8)*(1-(Platforme!$B$11+Platforme!$B$12-Platforme!$B$11*Platforme!$B$12))*Platforme!$B$27*(1+Platforme!$B$31)/(1+Platforme!$B$31))+Platforme!$B$8)/((1-(Platforme!$D$11+Platforme!$D$12-Platforme!$D$11*Platforme!$D$12))*(1-(Platforme!$D$14*Platforme!$D$15)))),Platforme!$D$16),CEILING(CEILING(IF(Platforme!$D$13=1,(((Sezoane!E12-Platforme!$B$8)*(1-(Platforme!$B$11+Platforme!$B$12-Platforme!$B$11*Platforme!$B$12))*1/(1+Platforme!$B$31))/(1-(Platforme!$D$11+Platforme!$D$12-Platforme!$D$11*Platforme!$D$12))+Platforme!$B$8)/(1-(Platforme!$D$14*Platforme!$D$15)),(((Sezoane!E12-Platforme!$B$8)*(1-(Platforme!$B$11+Platforme!$B$12-Platforme!$B$11*Platforme!$B$12))*1/(1+Platforme!$B$31))+Platforme!$B$8)/((1-(Platforme!$D$11+Platforme!$D$12-Platforme!$D$11*Platforme!$D$12))*(1-(Platforme!$D$14*Platforme!$D$15)))),Platforme!$D$16)*(1-Platforme!$B$26)+Sezoane!O12*Platforme!$B$26,Platforme!$D$16)))) | H11: =IF(Sezoane!$A$12="","",CEILING(IF(Platforme!$E$13=1,(((Sezoane!E12-Platforme!$B$8)*(1-(Platforme!$B$11+Platforme!$B$12-Platforme!$B$11*Platforme!$B$12))*1/(1+Platforme!$B$31))/(1-(Platforme!$E$11+Platforme!$E$12-Platforme!$E$11*Platforme!$E$12))+Platforme!$B$8)/(1-(Platforme!$E$14*Platforme!$E$15)),(((Sezoane!E12-Platforme!$B$8)*(1-(Platforme!$B$11+Platforme!$B$12-Platforme!$B$11*Platforme!$B$12))*1/(1+Platforme!$B$31))+Platforme!$B$8)/((1-(Platforme!$E$11+Platforme!$E$12-Platforme!$E$11*Platforme!$E$12))*(1-(Platforme!$E$14*Platforme!$E$15)))),Platforme!$E$16)) | I11: =IF(Sezoane!$A$12="","",(Sezoane!E12-Platforme!$B$8)*(1-(Platforme!$B$11+Platforme!$B$12-Platforme!$B$11*Platforme!$B$12))) | J11: =IF(Sezoane!$A$12="","",F11*(1-Platforme!$C$14)) | K11: =IF(Sezoane!$A$12="","",1-E11/MIN(J11,G11,H11)) | L11: =IF(Sezoane!$A$12="","",IFERROR(INDEX('Date actuale'!$C$6:$C$40,MATCH(A11,'Date actuale'!$A$6:$A$40,0)),"")) | M11: =IF(Sezoane!$A$12="","",IFERROR(INDEX('Date actuale'!$D$6:$D$40,MATCH(A11,'Date actuale'!$A$6:$A$40,0)),"")) | N11: =IF(Sezoane!$A$12="","",IFERROR(INDEX('Date actuale'!$E$6:$E$40,MATCH(A11,'Date actuale'!$A$6:$A$40,0)),"")) | O11: =IF(Sezoane!$A$12="","",Sezoane!M12) | P11: =IF(OR(Sezoane!$A$12="",N(Sezoane!O12)=0),"",Sezoane!O12) | Q11: =IF(Sezoane!$A$12="","",IF(Platforme!$D$13=1,(G11*(1-Platforme!$D$14)-Platforme!$B$8)*(1-(Platforme!$D$11+Platforme!$D$12-Platforme!$D$11*Platforme!$D$12)),G11*(1-Platforme!$D$14)*(1-(Platforme!$D$11+Platforme!$D$12-Platforme!$D$11*Platforme!$D$12))-Platforme!$B$8)) | R11: =IF(Sezoane!$A$12="","",Q11/U11-1) | S11: =IF(Sezoane!$A$12="","",G11*(1-Platforme!$B$28)) | T11: =IF(Sezoane!$A$12="","",IF(Platforme!$D$13=1,(S11*(1-Platforme!$D$14)-Platforme!$B$8)*(1-(Platforme!$D$11+Platforme!$D$12-Platforme!$D$11*Platforme!$D$12)),S11*(1-Platforme!$D$14)*(1-(Platforme!$D$11+Platforme!$D$12-Platforme!$D$11*Platforme!$D$12))-Platforme!$B$8)) | U11: =IF(Sezoane!$A$12="","",I11/(1+Platforme!$B$31))
A12: =IF(Sezoane!$A$13="","",Sezoane!A13) | B12: =IF(Sezoane!$A$13="","",Sezoane!C13) | C12: =IF(Sezoane!$A$13="","",Sezoane!D13) | D12: =IF(Sezoane!$A$13="","",Sezoane!F13) | E12: =IF(Sezoane!$A$13="","",Sezoane!E13) | F12: =IF(Sezoane!$A$13="","",CEILING(IF(Platforme!$C$13=1,(((Sezoane!E13-Platforme!$B$8)*(1-(Platforme!$B$11+Platforme!$B$12-Platforme!$B$11*Platforme!$B$12))*1/(1+Platforme!$B$31))/(1-(Platforme!$C$11+Platforme!$C$12-Platforme!$C$11*Platforme!$C$12))+Platforme!$B$8)/(1-(Platforme!$C$14*Platforme!$C$15)),(((Sezoane!E13-Platforme!$B$8)*(1-(Platforme!$B$11+Platforme!$B$12-Platforme!$B$11*Platforme!$B$12))*1/(1+Platforme!$B$31))+Platforme!$B$8)/((1-(Platforme!$C$11+Platforme!$C$12-Platforme!$C$11*Platforme!$C$12))*(1-(Platforme!$C$14*Platforme!$C$15)))),Platforme!$C$16)) | G12: =IF(Sezoane!$A$13="","",IF(N(Sezoane!O13)=0,CEILING(IF(Platforme!$D$13=1,(((Sezoane!E13-Platforme!$B$8)*(1-(Platforme!$B$11+Platforme!$B$12-Platforme!$B$11*Platforme!$B$12))*1/(1+Platforme!$B$31))/(1-(Platforme!$D$11+Platforme!$D$12-Platforme!$D$11*Platforme!$D$12))+Platforme!$B$8)/(1-(Platforme!$D$14*Platforme!$D$15)),(((Sezoane!E13-Platforme!$B$8)*(1-(Platforme!$B$11+Platforme!$B$12-Platforme!$B$11*Platforme!$B$12))*1/(1+Platforme!$B$31))+Platforme!$B$8)/((1-(Platforme!$D$11+Platforme!$D$12-Platforme!$D$11*Platforme!$D$12))*(1-(Platforme!$D$14*Platforme!$D$15)))),Platforme!$D$16),MAX(CEILING(IF(Platforme!$D$13=1,(((Sezoane!E13-Platforme!$B$8)*(1-(Platforme!$B$11+Platforme!$B$12-Platforme!$B$11*Platforme!$B$12))*Platforme!$B$27*(1+Platforme!$B$31)/(1+Platforme!$B$31))/(1-(Platforme!$D$11+Platforme!$D$12-Platforme!$D$11*Platforme!$D$12))+Platforme!$B$8)/(1-(Platforme!$D$14*Platforme!$D$15)),(((Sezoane!E13-Platforme!$B$8)*(1-(Platforme!$B$11+Platforme!$B$12-Platforme!$B$11*Platforme!$B$12))*Platforme!$B$27*(1+Platforme!$B$31)/(1+Platforme!$B$31))+Platforme!$B$8)/((1-(Platforme!$D$11+Platforme!$D$12-Platforme!$D$11*Platforme!$D$12))*(1-(Platforme!$D$14*Platforme!$D$15)))),Platforme!$D$16),CEILING(CEILING(IF(Platforme!$D$13=1,(((Sezoane!E13-Platforme!$B$8)*(1-(Platforme!$B$11+Platforme!$B$12-Platforme!$B$11*Platforme!$B$12))*1/(1+Platforme!$B$31))/(1-(Platforme!$D$11+Platforme!$D$12-Platforme!$D$11*Platforme!$D$12))+Platforme!$B$8)/(1-(Platforme!$D$14*Platforme!$D$15)),(((Sezoane!E13-Platforme!$B$8)*(1-(Platforme!$B$11+Platforme!$B$12-Platforme!$B$11*Platforme!$B$12))*1/(1+Platforme!$B$31))+Platforme!$B$8)/((1-(Platforme!$D$11+Platforme!$D$12-Platforme!$D$11*Platforme!$D$12))*(1-(Platforme!$D$14*Platforme!$D$15)))),Platforme!$D$16)*(1-Platforme!$B$26)+Sezoane!O13*Platforme!$B$26,Platforme!$D$16)))) | H12: =IF(Sezoane!$A$13="","",CEILING(IF(Platforme!$E$13=1,(((Sezoane!E13-Platforme!$B$8)*(1-(Platforme!$B$11+Platforme!$B$12-Platforme!$B$11*Platforme!$B$12))*1/(1+Platforme!$B$31))/(1-(Platforme!$E$11+Platforme!$E$12-Platforme!$E$11*Platforme!$E$12))+Platforme!$B$8)/(1-(Platforme!$E$14*Platforme!$E$15)),(((Sezoane!E13-Platforme!$B$8)*(1-(Platforme!$B$11+Platforme!$B$12-Platforme!$B$11*Platforme!$B$12))*1/(1+Platforme!$B$31))+Platforme!$B$8)/((1-(Platforme!$E$11+Platforme!$E$12-Platforme!$E$11*Platforme!$E$12))*(1-(Platforme!$E$14*Platforme!$E$15)))),Platforme!$E$16)) | I12: =IF(Sezoane!$A$13="","",(Sezoane!E13-Platforme!$B$8)*(1-(Platforme!$B$11+Platforme!$B$12-Platforme!$B$11*Platforme!$B$12))) | J12: =IF(Sezoane!$A$13="","",F12*(1-Platforme!$C$14)) | K12: =IF(Sezoane!$A$13="","",1-E12/MIN(J12,G12,H12)) | L12: =IF(Sezoane!$A$13="","",IFERROR(INDEX('Date actuale'!$C$6:$C$40,MATCH(A12,'Date actuale'!$A$6:$A$40,0)),"")) | M12: =IF(Sezoane!$A$13="","",IFERROR(INDEX('Date actuale'!$D$6:$D$40,MATCH(A12,'Date actuale'!$A$6:$A$40,0)),"")) | N12: =IF(Sezoane!$A$13="","",IFERROR(INDEX('Date actuale'!$E$6:$E$40,MATCH(A12,'Date actuale'!$A$6:$A$40,0)),"")) | O12: =IF(Sezoane!$A$13="","",Sezoane!M13) | P12: =IF(OR(Sezoane!$A$13="",N(Sezoane!O13)=0),"",Sezoane!O13) | Q12: =IF(Sezoane!$A$13="","",IF(Platforme!$D$13=1,(G12*(1-Platforme!$D$14)-Platforme!$B$8)*(1-(Platforme!$D$11+Platforme!$D$12-Platforme!$D$11*Platforme!$D$12)),G12*(1-Platforme!$D$14)*(1-(Platforme!$D$11+Platforme!$D$12-Platforme!$D$11*Platforme!$D$12))-Platforme!$B$8)) | R12: =IF(Sezoane!$A$13="","",Q12/U12-1) | S12: =IF(Sezoane!$A$13="","",G12*(1-Platforme!$B$28)) | T12: =IF(Sezoane!$A$13="","",IF(Platforme!$D$13=1,(S12*(1-Platforme!$D$14)-Platforme!$B$8)*(1-(Platforme!$D$11+Platforme!$D$12-Platforme!$D$11*Platforme!$D$12)),S12*(1-Platforme!$D$14)*(1-(Platforme!$D$11+Platforme!$D$12-Platforme!$D$11*Platforme!$D$12))-Platforme!$B$8)) | U12: =IF(Sezoane!$A$13="","",I12/(1+Platforme!$B$31))
A13: =IF(Sezoane!$A$14="","",Sezoane!A14) | B13: =IF(Sezoane!$A$14="","",Sezoane!C14) | C13: =IF(Sezoane!$A$14="","",Sezoane!D14) | D13: =IF(Sezoane!$A$14="","",Sezoane!F14) | E13: =IF(Sezoane!$A$14="","",Sezoane!E14) | F13: =IF(Sezoane!$A$14="","",CEILING(IF(Platforme!$C$13=1,(((Sezoane!E14-Platforme!$B$8)*(1-(Platforme!$B$11+Platforme!$B$12-Platforme!$B$11*Platforme!$B$12))*1/(1+Platforme!$B$31))/(1-(Platforme!$C$11+Platforme!$C$12-Platforme!$C$11*Platforme!$C$12))+Platforme!$B$8)/(1-(Platforme!$C$14*Platforme!$C$15)),(((Sezoane!E14-Platforme!$B$8)*(1-(Platforme!$B$11+Platforme!$B$12-Platforme!$B$11*Platforme!$B$12))*1/(1+Platforme!$B$31))+Platforme!$B$8)/((1-(Platforme!$C$11+Platforme!$C$12-Platforme!$C$11*Platforme!$C$12))*(1-(Platforme!$C$14*Platforme!$C$15)))),Platforme!$C$16)) | G13: =IF(Sezoane!$A$14="","",IF(N(Sezoane!O14)=0,CEILING(IF(Platforme!$D$13=1,(((Sezoane!E14-Platforme!$B$8)*(1-(Platforme!$B$11+Platforme!$B$12-Platforme!$B$11*Platforme!$B$12))*1/(1+Platforme!$B$31))/(1-(Platforme!$D$11+Platforme!$D$12-Platforme!$D$11*Platforme!$D$12))+Platforme!$B$8)/(1-(Platforme!$D$14*Platforme!$D$15)),(((Sezoane!E14-Platforme!$B$8)*(1-(Platforme!$B$11+Platforme!$B$12-Platforme!$B$11*Platforme!$B$12))*1/(1+Platforme!$B$31))+Platforme!$B$8)/((1-(Platforme!$D$11+Platforme!$D$12-Platforme!$D$11*Platforme!$D$12))*(1-(Platforme!$D$14*Platforme!$D$15)))),Platforme!$D$16),MAX(CEILING(IF(Platforme!$D$13=1,(((Sezoane!E14-Platforme!$B$8)*(1-(Platforme!$B$11+Platforme!$B$12-Platforme!$B$11*Platforme!$B$12))*Platforme!$B$27*(1+Platforme!$B$31)/(1+Platforme!$B$31))/(1-(Platforme!$D$11+Platforme!$D$12-Platforme!$D$11*Platforme!$D$12))+Platforme!$B$8)/(1-(Platforme!$D$14*Platforme!$D$15)),(((Sezoane!E14-Platforme!$B$8)*(1-(Platforme!$B$11+Platforme!$B$12-Platforme!$B$11*Platforme!$B$12))*Platforme!$B$27*(1+Platforme!$B$31)/(1+Platforme!$B$31))+Platforme!$B$8)/((1-(Platforme!$D$11+Platforme!$D$12-Platforme!$D$11*Platforme!$D$12))*(1-(Platforme!$D$14*Platforme!$D$15)))),Platforme!$D$16),CEILING(CEILING(IF(Platforme!$D$13=1,(((Sezoane!E14-Platforme!$B$8)*(1-(Platforme!$B$11+Platforme!$B$12-Platforme!$B$11*Platforme!$B$12))*1/(1+Platforme!$B$31))/(1-(Platforme!$D$11+Platforme!$D$12-Platforme!$D$11*Platforme!$D$12))+Platforme!$B$8)/(1-(Platforme!$D$14*Platforme!$D$15)),(((Sezoane!E14-Platforme!$B$8)*(1-(Platforme!$B$11+Platforme!$B$12-Platforme!$B$11*Platforme!$B$12))*1/(1+Platforme!$B$31))+Platforme!$B$8)/((1-(Platforme!$D$11+Platforme!$D$12-Platforme!$D$11*Platforme!$D$12))*(1-(Platforme!$D$14*Platforme!$D$15)))),Platforme!$D$16)*(1-Platforme!$B$26)+Sezoane!O14*Platforme!$B$26,Platforme!$D$16)))) | H13: =IF(Sezoane!$A$14="","",CEILING(IF(Platforme!$E$13=1,(((Sezoane!E14-Platforme!$B$8)*(1-(Platforme!$B$11+Platforme!$B$12-Platforme!$B$11*Platforme!$B$12))*1/(1+Platforme!$B$31))/(1-(Platforme!$E$11+Platforme!$E$12-Platforme!$E$11*Platforme!$E$12))+Platforme!$B$8)/(1-(Platforme!$E$14*Platforme!$E$15)),(((Sezoane!E14-Platforme!$B$8)*(1-(Platforme!$B$11+Platforme!$B$12-Platforme!$B$11*Platforme!$B$12))*1/(1+Platforme!$B$31))+Platforme!$B$8)/((1-(Platforme!$E$11+Platforme!$E$12-Platforme!$E$11*Platforme!$E$12))*(1-(Platforme!$E$14*Platforme!$E$15)))),Platforme!$E$16)) | I13: =IF(Sezoane!$A$14="","",(Sezoane!E14-Platforme!$B$8)*(1-(Platforme!$B$11+Platforme!$B$12-Platforme!$B$11*Platforme!$B$12))) | J13: =IF(Sezoane!$A$14="","",F13*(1-Platforme!$C$14)) | K13: =IF(Sezoane!$A$14="","",1-E13/MIN(J13,G13,H13)) | L13: =IF(Sezoane!$A$14="","",IFERROR(INDEX('Date actuale'!$C$6:$C$40,MATCH(A13,'Date actuale'!$A$6:$A$40,0)),"")) | M13: =IF(Sezoane!$A$14="","",IFERROR(INDEX('Date actuale'!$D$6:$D$40,MATCH(A13,'Date actuale'!$A$6:$A$40,0)),"")) | N13: =IF(Sezoane!$A$14="","",IFERROR(INDEX('Date actuale'!$E$6:$E$40,MATCH(A13,'Date actuale'!$A$6:$A$40,0)),"")) | O13: =IF(Sezoane!$A$14="","",Sezoane!M14) | P13: =IF(OR(Sezoane!$A$14="",N(Sezoane!O14)=0),"",Sezoane!O14) | Q13: =IF(Sezoane!$A$14="","",IF(Platforme!$D$13=1,(G13*(1-Platforme!$D$14)-Platforme!$B$8)*(1-(Platforme!$D$11+Platforme!$D$12-Platforme!$D$11*Platforme!$D$12)),G13*(1-Platforme!$D$14)*(1-(Platforme!$D$11+Platforme!$D$12-Platforme!$D$11*Platforme!$D$12))-Platforme!$B$8)) | R13: =IF(Sezoane!$A$14="","",Q13/U13-1) | S13: =IF(Sezoane!$A$14="","",G13*(1-Platforme!$B$28)) | T13: =IF(Sezoane!$A$14="","",IF(Platforme!$D$13=1,(S13*(1-Platforme!$D$14)-Platforme!$B$8)*(1-(Platforme!$D$11+Platforme!$D$12-Platforme!$D$11*Platforme!$D$12)),S13*(1-Platforme!$D$14)*(1-(Platforme!$D$11+Platforme!$D$12-Platforme!$D$11*Platforme!$D$12))-Platforme!$B$8)) | U13: =IF(Sezoane!$A$14="","",I13/(1+Platforme!$B$31))
A14: =IF(Sezoane!$A$15="","",Sezoane!A15) | B14: =IF(Sezoane!$A$15="","",Sezoane!C15) | C14: =IF(Sezoane!$A$15="","",Sezoane!D15) | D14: =IF(Sezoane!$A$15="","",Sezoane!F15) | E14: =IF(Sezoane!$A$15="","",Sezoane!E15) | F14: =IF(Sezoane!$A$15="","",CEILING(IF(Platforme!$C$13=1,(((Sezoane!E15-Platforme!$B$8)*(1-(Platforme!$B$11+Platforme!$B$12-Platforme!$B$11*Platforme!$B$12))*1/(1+Platforme!$B$31))/(1-(Platforme!$C$11+Platforme!$C$12-Platforme!$C$11*Platforme!$C$12))+Platforme!$B$8)/(1-(Platforme!$C$14*Platforme!$C$15)),(((Sezoane!E15-Platforme!$B$8)*(1-(Platforme!$B$11+Platforme!$B$12-Platforme!$B$11*Platforme!$B$12))*1/(1+Platforme!$B$31))+Platforme!$B$8)/((1-(Platforme!$C$11+Platforme!$C$12-Platforme!$C$11*Platforme!$C$12))*(1-(Platforme!$C$14*Platforme!$C$15)))),Platforme!$C$16)) | G14: =IF(Sezoane!$A$15="","",IF(N(Sezoane!O15)=0,CEILING(IF(Platforme!$D$13=1,(((Sezoane!E15-Platforme!$B$8)*(1-(Platforme!$B$11+Platforme!$B$12-Platforme!$B$11*Platforme!$B$12))*1/(1+Platforme!$B$31))/(1-(Platforme!$D$11+Platforme!$D$12-Platforme!$D$11*Platforme!$D$12))+Platforme!$B$8)/(1-(Platforme!$D$14*Platforme!$D$15)),(((Sezoane!E15-Platforme!$B$8)*(1-(Platforme!$B$11+Platforme!$B$12-Platforme!$B$11*Platforme!$B$12))*1/(1+Platforme!$B$31))+Platforme!$B$8)/((1-(Platforme!$D$11+Platforme!$D$12-Platforme!$D$11*Platforme!$D$12))*(1-(Platforme!$D$14*Platforme!$D$15)))),Platforme!$D$16),MAX(CEILING(IF(Platforme!$D$13=1,(((Sezoane!E15-Platforme!$B$8)*(1-(Platforme!$B$11+Platforme!$B$12-Platforme!$B$11*Platforme!$B$12))*Platforme!$B$27*(1+Platforme!$B$31)/(1+Platforme!$B$31))/(1-(Platforme!$D$11+Platforme!$D$12-Platforme!$D$11*Platforme!$D$12))+Platforme!$B$8)/(1-(Platforme!$D$14*Platforme!$D$15)),(((Sezoane!E15-Platforme!$B$8)*(1-(Platforme!$B$11+Platforme!$B$12-Platforme!$B$11*Platforme!$B$12))*Platforme!$B$27*(1+Platforme!$B$31)/(1+Platforme!$B$31))+Platforme!$B$8)/((1-(Platforme!$D$11+Platforme!$D$12-Platforme!$D$11*Platforme!$D$12))*(1-(Platforme!$D$14*Platforme!$D$15)))),Platforme!$D$16),CEILING(CEILING(IF(Platforme!$D$13=1,(((Sezoane!E15-Platforme!$B$8)*(1-(Platforme!$B$11+Platforme!$B$12-Platforme!$B$11*Platforme!$B$12))*1/(1+Platforme!$B$31))/(1-(Platforme!$D$11+Platforme!$D$12-Platforme!$D$11*Platforme!$D$12))+Platforme!$B$8)/(1-(Platforme!$D$14*Platforme!$D$15)),(((Sezoane!E15-Platforme!$B$8)*(1-(Platforme!$B$11+Platforme!$B$12-Platforme!$B$11*Platforme!$B$12))*1/(1+Platforme!$B$31))+Platforme!$B$8)/((1-(Platforme!$D$11+Platforme!$D$12-Platforme!$D$11*Platforme!$D$12))*(1-(Platforme!$D$14*Platforme!$D$15)))),Platforme!$D$16)*(1-Platforme!$B$26)+Sezoane!O15*Platforme!$B$26,Platforme!$D$16)))) | H14: =IF(Sezoane!$A$15="","",CEILING(IF(Platforme!$E$13=1,(((Sezoane!E15-Platforme!$B$8)*(1-(Platforme!$B$11+Platforme!$B$12-Platforme!$B$11*Platforme!$B$12))*1/(1+Platforme!$B$31))/(1-(Platforme!$E$11+Platforme!$E$12-Platforme!$E$11*Platforme!$E$12))+Platforme!$B$8)/(1-(Platforme!$E$14*Platforme!$E$15)),(((Sezoane!E15-Platforme!$B$8)*(1-(Platforme!$B$11+Platforme!$B$12-Platforme!$B$11*Platforme!$B$12))*1/(1+Platforme!$B$31))+Platforme!$B$8)/((1-(Platforme!$E$11+Platforme!$E$12-Platforme!$E$11*Platforme!$E$12))*(1-(Platforme!$E$14*Platforme!$E$15)))),Platforme!$E$16)) | I14: =IF(Sezoane!$A$15="","",(Sezoane!E15-Platforme!$B$8)*(1-(Platforme!$B$11+Platforme!$B$12-Platforme!$B$11*Platforme!$B$12))) | J14: =IF(Sezoane!$A$15="","",F14*(1-Platforme!$C$14)) | K14: =IF(Sezoane!$A$15="","",1-E14/MIN(J14,G14,H14)) | L14: =IF(Sezoane!$A$15="","",IFERROR(INDEX('Date actuale'!$C$6:$C$40,MATCH(A14,'Date actuale'!$A$6:$A$40,0)),"")) | M14: =IF(Sezoane!$A$15="","",IFERROR(INDEX('Date actuale'!$D$6:$D$40,MATCH(A14,'Date actuale'!$A$6:$A$40,0)),"")) | N14: =IF(Sezoane!$A$15="","",IFERROR(INDEX('Date actuale'!$E$6:$E$40,MATCH(A14,'Date actuale'!$A$6:$A$40,0)),"")) | O14: =IF(Sezoane!$A$15="","",Sezoane!M15) | P14: =IF(OR(Sezoane!$A$15="",N(Sezoane!O15)=0),"",Sezoane!O15) | Q14: =IF(Sezoane!$A$15="","",IF(Platforme!$D$13=1,(G14*(1-Platforme!$D$14)-Platforme!$B$8)*(1-(Platforme!$D$11+Platforme!$D$12-Platforme!$D$11*Platforme!$D$12)),G14*(1-Platforme!$D$14)*(1-(Platforme!$D$11+Platforme!$D$12-Platforme!$D$11*Platforme!$D$12))-Platforme!$B$8)) | R14: =IF(Sezoane!$A$15="","",Q14/U14-1) | S14: =IF(Sezoane!$A$15="","",G14*(1-Platforme!$B$28)) | T14: =IF(Sezoane!$A$15="","",IF(Platforme!$D$13=1,(S14*(1-Platforme!$D$14)-Platforme!$B$8)*(1-(Platforme!$D$11+Platforme!$D$12-Platforme!$D$11*Platforme!$D$12)),S14*(1-Platforme!$D$14)*(1-(Platforme!$D$11+Platforme!$D$12-Platforme!$D$11*Platforme!$D$12))-Platforme!$B$8)) | U14: =IF(Sezoane!$A$15="","",I14/(1+Platforme!$B$31))
